<?xml version="1.0" ?>
<!-- =================================================================================== -->
<!-- |    This document was autogenerated by xacro from /home/daniel/Desktop/AgarreDual/ur5/src/universal_robot/ur_description/urdf/ur5_robot.urdf.xacro | -->
<!-- |    EDITING THIS FILE BY HAND IS NOT RECOMMENDED                                 | -->
<!-- =================================================================================== -->
<robot name="ur5">
    <gazebo>
        <plugin filename="libgazebo_ros_control.so" name="ros_control">
            <!--robotNamespace>/</robotNamespace-->
            <!--robotSimType>gazebo_ros_control/DefaultRobotHWSim</robotSimType-->
        </plugin>
        <!--
    <plugin name="gazebo_ros_power_monitor_controller" filename="libgazebo_ros_power_monitor.so">
      <alwaysOn>true</alwaysOn>
      <updateRate>1.0</updateRate>
      <timeout>5</timeout>
      <powerStateTopic>power_state</powerStateTopic>
      <powerStateRate>10.0</powerStateRate>
      <fullChargeCapacity>87.78</fullChargeCapacity>     
      <dischargeRate>-474</dischargeRate>
      <chargeRate>525</chargeRate>
      <dischargeVoltage>15.52</dischargeVoltage>
      <chargeVoltage>16.41</chargeVoltage>
    </plugin>
-->
        <plugin name="gazebo_ros_control">
            <robotNamespace>/</robotNamespace>
        </plugin>
    </gazebo>
    <!-- measured from model -->
    <!--property name="shoulder_height" value="0.089159" /-->
    <!--property name="shoulder_offset" value="0.13585" /-->
    <!-- shoulder_offset - elbow_offset + wrist_1_length = 0.10915 -->
    <!--property name="upper_arm_length" value="0.42500" /-->
    <!--property name="elbow_offset" value="0.1197" /-->
    <!-- CAD measured -->
    <!--property name="forearm_length" value="0.39225" /-->
    <!--property name="wrist_1_length" value="0.093" /-->
    <!-- CAD measured -->
    <!--property name="wrist_2_length" value="0.09465" /-->
    <!-- In CAD this distance is 0.930, but in the spec it is 0.09465 -->
    <!--property name="wrist_3_length" value="0.0823" /-->
    <!-- manually measured -->
    <link name="base_link">
        <visual>
            <geometry>
                <mesh filename="package://ur_description/meshes/ur5/visual/base.dae" />
            </geometry>
            <material name="LightGrey">
                <color rgba="0.7 0.7 0.7 1.0" />
            </material>
        </visual>
        <collision>
            <geometry>
                <mesh filename="package://ur_description/meshes/ur5/collision/base.stl" />
            </geometry>
        </collision>
        <inertial>
            <mass value="4.0" />
            <origin rpy="0 0 0" xyz="0.0 0.0 0.0" />
            <inertia ixx="0.00443333156" ixy="0.0" ixz="0.0" iyy="0.00443333156" iyz="0.0" izz="0.0072" />
        </inertial>
    </link>
    <joint name="shoulder_pan_joint" type="revolute">
        <parent link="base_link" />
        <child link="shoulder_link" />
        <origin rpy="0.0 0.0 0.0" xyz="0.0 0.0 0.089159" />
        <axis xyz="0 0 1" />
        <limit effort="150.0" lower="-6.283185307179586" upper="6.283185307179586" velocity="3.15" />
        <dynamics damping="0.0" friction="0.0" />
    </joint>
    <link name="shoulder_link">
        <visual>
            <geometry>
                <mesh filename="package://ur_description/meshes/ur5/visual/shoulder.dae" />
            </geometry>
            <material name="LightGrey">
                <color rgba="0.7 0.7 0.7 1.0" />
            </material>
        </visual>
        <collision>
            <geometry>
                <mesh filename="package://ur_description/meshes/ur5/collision/shoulder.stl" />
            </geometry>
        </collision>
        <inertial>
            <mass value="3.7" />
            <origin rpy="0 0 0" xyz="0.0 0.0 0.0" />
            <inertia ixx="0.010267495893" ixy="0.0" ixz="0.0" iyy="0.010267495893" iyz="0.0" izz="0.00666" />
        </inertial>
    </link>
    <joint name="shoulder_lift_joint" type="revolute">
        <parent link="shoulder_link" />
        <child link="upper_arm_link" />
        <origin rpy="0.0 1.5707963267948966 0.0" xyz="0.0 0.13585 0.0" />
        <axis xyz="0 1 0" />
        <limit effort="150.0" lower="-6.283185307179586" upper="6.283185307179586" velocity="3.15" />
        <dynamics damping="0.0" friction="0.0" />
    </joint>
    <link name="upper_arm_link">
        <visual>
            <geometry>
                <mesh filename="package://ur_description/meshes/ur5/visual/upperarm.dae" />
            </geometry>
            <material name="LightGrey">
                <color rgba="0.7 0.7 0.7 1.0" />
            </material>
        </visual>
        <collision>
            <geometry>
                <mesh filename="package://ur_description/meshes/ur5/collision/upperarm.stl" />
            </geometry>
        </collision>
        <inertial>
            <mass value="8.393" />
            <origin rpy="0 0 0" xyz="0.0 0.0 0.28" />
            <inertia ixx="0.22689067591036005" ixy="0.0" ixz="0.0" iyy="0.22689067591036005" iyz="0.0" izz="0.0151074" />
        </inertial>
    </link>
    <joint name="elbow_joint" type="revolute">
        <parent link="upper_arm_link" />
        <child link="forearm_link" />
        <origin rpy="0.0 0.0 0.0" xyz="0.0 -0.1197 0.425" />
        <axis xyz="0 1 0" />
        <limit effort="150.0" lower="-3.141592653589793" upper="3.141592653589793" velocity="3.15" />
        <dynamics damping="0.0" friction="0.0" />
    </joint>
    <link name="forearm_link">
        <visual>
            <geometry>
                <mesh filename="package://ur_description/meshes/ur5/visual/forearm.dae" />
            </geometry>
            <material name="LightGrey">
                <color rgba="0.7 0.7 0.7 1.0" />
            </material>
        </visual>
        <collision>
            <geometry>
                <mesh filename="package://ur_description/meshes/ur5/collision/forearm.stl" />
            </geometry>
        </collision>
        <inertial>
            <mass value="2.275" />
            <origin rpy="0 0 0" xyz="0.0 0.0 0.196125" />
            <inertia ixx="0.03121679102890359" ixy="0.0" ixz="0.0" iyy="0.03121679102890359" iyz="0.0" izz="0.004095" />
        </inertial>
    </link>
    <joint name="wrist_1_joint" type="revolute">
        <parent link="forearm_link" />
        <child link="wrist_1_link" />
        <origin rpy="0.0 1.5707963267948966 0.0" xyz="0.0 0.0 0.39225" />
        <axis xyz="0 1 0" />
        <limit effort="28.0" lower="-6.283185307179586" upper="6.283185307179586" velocity="3.2" />
        <dynamics damping="0.0" friction="0.0" />
    </joint>
    <link name="wrist_1_link">
        <visual>
            <geometry>
                <mesh filename="package://ur_description/meshes/ur5/visual/wrist1.dae" />
            </geometry>
            <material name="LightGrey">
                <color rgba="0.7 0.7 0.7 1.0" />
            </material>
        </visual>
        <collision>
            <geometry>
                <mesh filename="package://ur_description/meshes/ur5/collision/wrist1.stl" />
            </geometry>
        </collision>
        <inertial>
            <mass value="1.219" />
            <origin rpy="0 0 0" xyz="0.0 0.093 0.0" />
            <inertia ixx="0.0025598989760400002" ixy="0.0" ixz="0.0" iyy="0.0025598989760400002" iyz="0.0" izz="0.0021942" />
        </inertial>
    </link>
    <joint name="wrist_2_joint" type="revolute">
        <parent link="wrist_1_link" />
        <child link="wrist_2_link" />
        <origin rpy="0.0 0.0 0.0" xyz="0.0 0.093 0.0" />
        <axis xyz="0 0 1" />
        <limit effort="28.0" lower="-6.283185307179586" upper="6.283185307179586" velocity="3.2" />
        <dynamics damping="0.0" friction="0.0" />
    </joint>
    <link name="wrist_2_link">
        <visual>
            <geometry>
                <mesh filename="package://ur_description/meshes/ur5/visual/wrist2.dae" />
            </geometry>
            <material name="LightGrey">
                <color rgba="0.7 0.7 0.7 1.0" />
            </material>
        </visual>
        <collision>
            <geometry>
                <mesh filename="package://ur_description/meshes/ur5/collision/wrist2.stl" />
            </geometry>
        </collision>
        <inertial>
            <mass value="1.219" />
            <origin rpy="0 0 0" xyz="0.0 0.0 0.09465" />
            <inertia ixx="0.0025598989760400002" ixy="0.0" ixz="0.0" iyy="0.0025598989760400002" iyz="0.0" izz="0.0021942" />
        </inertial>
    </link>
    <joint name="wrist_3_joint" type="revolute">
        <parent link="wrist_2_link" />
        <child link="wrist_3_link" />
        <origin rpy="0.0 0.0 0.0" xyz="0.0 0.0 0.09465" />
        <axis xyz="0 1 0" />
        <limit effort="28.0" lower="-6.283185307179586" upper="6.283185307179586" velocity="3.2" />
        <dynamics damping="0.0" friction="0.0" />
    </joint>
    <link name="wrist_3_link">
        <visual>
            <geometry>
                <mesh filename="package://ur_description/meshes/ur5/visual/wrist3.dae" />
            </geometry>
            <material name="LightGrey">
                <color rgba="0.7 0.7 0.7 1.0" />
            </material>
        </visual>
        <collision>
            <geometry>
                <mesh filename="package://ur_description/meshes/ur5/collision/wrist3.stl" />
            </geometry>
        </collision>
        <inertial>
            <mass value="0.1879" />
            <origin rpy="1.5707963267948966 0 0" xyz="0.0 0.06505 0.0" />
            <inertia ixx="8.469589112163e-05" ixy="0.0" ixz="0.0" iyy="8.469589112163e-05" iyz="0.0" izz="0.0001321171875" />
        </inertial>
    </link>
    <joint name="ee_fixed_joint" type="fixed">
        <parent link="wrist_3_link" />
        <child link="ee_link" />
        <origin rpy="0.0 0.0 1.5707963267948966" xyz="0.0 0.0823 0.0" />
    </joint>
    <link name="ee_link">
        <collision>
            <geometry>
                <box size="0.01 0.01 0.01" />
            </geometry>
            <origin rpy="0 0 0" xyz="-0.01 0 0" />
        </collision>
        <inertial>
            <mass value="0.1" />
            <origin xyz="0 0 0" rpy="0 0 0" />
            <inertia ixx="0.03" iyy="0.03" izz="0.03" ixy="0.0" ixz="0.0" iyz="0.0" />
        </inertial>
    </link>
    <transmission name="shoulder_pan_trans">
        <type>transmission_interface/SimpleTransmission</type>
        <joint name="shoulder_pan_joint">
            <hardwareInterface>EffortJointInterface</hardwareInterface>
        </joint>
        <actuator name="shoulder_pan_motor">
            <mechanicalReduction>1</mechanicalReduction>
            <hardwareInterface>hardware_interface/EffortJointInterface</hardwareInterface>
        </actuator>
    </transmission>
    <transmission name="shoulder_lift_trans">
        <type>transmission_interface/SimpleTransmission</type>
        <joint name="shoulder_lift_joint">
            <hardwareInterface>EffortJointInterface</hardwareInterface>
        </joint>
        <actuator name="shoulder_lift_motor">
            <mechanicalReduction>1</mechanicalReduction>
            <hardwareInterface>hardware_interface/EffortJointInterface</hardwareInterface>
        </actuator>
    </transmission>
    <transmission name="elbow_trans">
        <type>transmission_interface/SimpleTransmission</type>
        <joint name="elbow_joint">
            <hardwareInterface>EffortJointInterface</hardwareInterface>
        </joint>
        <actuator name="elbow_motor">
            <mechanicalReduction>1</mechanicalReduction>
            <hardwareInterface>hardware_interface/EffortJointInterface</hardwareInterface>
        </actuator>
    </transmission>
    <transmission name="wrist_1_trans">
        <type>transmission_interface/SimpleTransmission</type>
        <joint name="wrist_1_joint">
            <hardwareInterface>EffortJointInterface</hardwareInterface>
        </joint>
        <actuator name="wrist_1_motor">
            <mechanicalReduction>1</mechanicalReduction>
            <hardwareInterface>hardware_interface/EffortJointInterface</hardwareInterface>
        </actuator>
    </transmission>
    <transmission name="wrist_2_trans">
        <type>transmission_interface/SimpleTransmission</type>
        <joint name="wrist_2_joint">
            <hardwareInterface>EffortJointInterface</hardwareInterface>
        </joint>
        <actuator name="wrist_2_motor">
            <mechanicalReduction>1</mechanicalReduction>
            <hardwareInterface>hardware_interface/EffortJointInterface</hardwareInterface>
        </actuator>
    </transmission>
    <transmission name="wrist_3_trans">
        <type>transmission_interface/SimpleTransmission</type>
        <joint name="wrist_3_joint">
            <hardwareInterface>EffortJointInterface</hardwareInterface>
        </joint>
        <actuator name="wrist_3_motor">
            <mechanicalReduction>1</mechanicalReduction>
            <hardwareInterface>hardware_interface/EffortJointInterface</hardwareInterface>
        </actuator>
    </transmission>
    <gazebo reference="shoulder_link">
        <selfCollide>true</selfCollide>
    </gazebo>
    <gazebo reference="upper_arm_link">
        <selfCollide>true</selfCollide>
    </gazebo>
    <gazebo reference="forearm_link">
        <selfCollide>true</selfCollide>
    </gazebo>
    <gazebo reference="wrist_1_link">
        <selfCollide>true</selfCollide>
    </gazebo>
    <gazebo reference="wrist_3_link">
        <selfCollide>true</selfCollide>
    </gazebo>
    <gazebo reference="wrist_2_link">
        <selfCollide>true</selfCollide>
    </gazebo>
    <gazebo reference="ee_link">
        <selfCollide>true</selfCollide>
    </gazebo>
    <!-- ROS base_link to UR 'Base' Coordinates transform -->
    <link name="base" />
    <joint name="base_link-base_fixed_joint" type="fixed">
        <!-- NOTE: this rotation is only needed as long as base_link itself is
                 not corrected wrt the real robot (ie: rotated over 180
                 degrees)
      -->
        <origin rpy="0 0 -3.141592653589793" xyz="0 0 0" />
        <parent link="base_link" />
        <child link="base" />
    </joint>
    <!-- Frame coincident with all-zeros TCP on UR controller -->
    <link name="tool0" />
    <joint name="wrist_3_link-tool0_fixed_joint" type="fixed">
        <origin rpy="-1.5707963267948966 0 0" xyz="0 0.0823 0" />
        <parent link="wrist_3_link" />
        <child link="tool0" />
    </joint>
    <joint name="camera_joint" type="fixed">
        <origin rpy="0 -0.2 2.39" xyz="1.0 -1.0 0.15" />
        <parent link="base_link" />
        <child link="camera_link" />
    </joint>
    <link name="camera_link">
        <visual>
            <geometry>
                <mesh filename="package://ur_description/meshes/DAE/camera/camera.dae" />
            </geometry>
        </visual>
        <collision>
            <geometry>
                <mesh filename="package://ur_description/meshes/STL/camera/camera.stl" />
            </geometry>
        </collision>
        <inertial>
            <origin xyz="0 0 0" rpy="0 0 0" />
            <mass value="0.1" />
            <inertia ixx="0.00001" ixy="0" ixz="0" iyy="0.00001" iyz="0" izz="0.00001" />
        </inertial>
    </link>
    <gazebo reference="camera_link">
        <sensor name="robot_camera" type="camera">
            <update_rate>30.0</update_rate>
            <camera name="robot_camera">
                <pose>0 0 0 0 0 0</pose>
                <horizontal_fov>1.3962634</horizontal_fov>
                <image>
                    <width>640</width>
                    <height>480</height>
                    <format>R8G8B8</format>
                </image>
                <clip>
                    <near>0.02</near>
                    <far>300</far>
                </clip>
                <noise>
                    <type>gaussian</type>
                    <mean>0.0</mean>
                    <stddev>0.007</stddev>
                </noise>
            </camera>
            <plugin filename="libgazebo_ros_camera.so" name="camera_controller">
                <alwaysOn>true</alwaysOn>
                <updateRate>0.0</updateRate>
                <cameraName>robot_camera</cameraName>
                <imageTopicName>image_raw</imageTopicName>
                <cameraInfoTopicName>camera_info</cameraInfoTopicName>
                <frameName>camera_link</frameName>
                <hackBaseline>0.0</hackBaseline>
                <distortionK1>0.0</distortionK1>
                <distortionK2>0.0</distortionK2>
                <distortionK3>0.0</distortionK3>
                <distortionT1>0.0</distortionT1>
                <distortionT2>0.0</distortionT2>
            </plugin>
        </sensor>
    </gazebo>
    <link name="world" />
    <joint name="world_joint" type="fixed">
        <parent link="world" />
        <child link="base_link" />
        <origin rpy="0.0 0.0 0.0" xyz="0.0 0.0 0.0" />
    </joint>
    <link name="robotiq_arg2f_base_link">
        <inertial>
            <origin rpy="0 0 0" xyz="8.625E-08 -4.6583E-06 0.03145" />
            <mass value="0.22652" />
            <inertia ixx="0.00020005" ixy="-4.2442E-10" ixz="-2.9069E-10" iyy="0.00017832" iyz="-3.4402E-08" izz="0.00013478" />
        </inertial>
        <visual>
            <origin rpy="0 0 0" xyz="0 0 0" />
            <geometry>
                <mesh filename="package://robotiq_2f_140_gripper_visualization/meshes/robotiq_arg2f_base_link_fine.stl" />
            </geometry>
            <material name="">
                <color rgba="0.1 0.1 0.1 1" />
            </material>
        </visual>
        <collision>
            <origin rpy="0 0 1.5707963267948966" xyz="0 0 0" />
            <geometry>
                <mesh filename="package://robotiq_2f_140_gripper_visualization/meshes/robotiq_arg2f_base_link_coarse.stl" />
            </geometry>
        </collision>
    </link>
    <joint name="base" type="fixed">
        <parent link="tool0" />
        <child link="robotiq_arg2f_base_link" />
        <origin rpy="0 0 1.57" xyz="0.0 0.0 0.005" />
    </joint>
    <link name="left_outer_knuckle">
        <inertial>
            <origin rpy="0 0 0" xyz="-0.000200000000003065 0.0199435877845359 0.0292245259211331" />
            <mass value="0.00853198276973456" />
            <inertia ixx="2.89328108496468E-06" ixy="-1.57935047237397E-19" ixz="-1.93980378593255E-19" iyy="1.86719750325683E-06" iyz="-1.21858577871576E-06" izz="1.21905238907251E-06" />
        </inertial>
        <visual>
            <origin rpy="0 0 0" xyz="0 0 0" />
            <geometry>
                <mesh filename="package://robotiq_2f_140_gripper_visualization/meshes/robotiq_arg2f_140_outer_knuckle.stl" />
            </geometry>
            <material name="">
                <color rgba="0.792156862745098 0.819607843137255 0.933333333333333 1" />
            </material>
        </visual>
        <collision>
            <origin rpy="0 0 0" xyz="0 0 0" />
            <geometry>
                <mesh filename="package://robotiq_2f_140_gripper_visualization/meshes/robotiq_arg2f_140_outer_knuckle.stl" />
            </geometry>
        </collision>
    </link>
    <link name="left_outer_finger">
        <inertial>
            <origin rpy="0 0 0" xyz="0.00030115855001899 0.0373907951953854 -0.0208027427000385" />
            <mass value="0.022614240507152" />
            <inertia ixx="1.52518312458174E-05" ixy="9.76583423954399E-10" ixz="-5.43838577022588E-10" iyy="6.17694243867776E-06" iyz="6.78636130740228E-06" izz="1.16494917907219E-05" />
        </inertial>
        <visual>
            <origin rpy="0 0 0" xyz="0 0 0" />
            <geometry>
                <mesh filename="package://robotiq_2f_140_gripper_visualization/meshes/robotiq_arg2f_140_outer_finger.stl" />
            </geometry>
            <material name="">
                <color rgba="0.1 0.1 0.1 1" />
            </material>
        </visual>
        <collision>
            <origin rpy="0 0 0" xyz="0 0 0" />
            <geometry>
                <mesh filename="package://robotiq_2f_140_gripper_visualization/meshes/robotiq_arg2f_140_outer_finger.stl" />
            </geometry>
        </collision>
    </link>
    <link name="left_inner_finger">
        <inertial>
            <origin rpy="0 0 0" xyz="0.000299999999999317 0.0160078233491243 -0.0136945669206257" />
            <mass value="0.0104003125914103" />
            <inertia ixx="2.71909453810972E-06" ixy="1.35402465472579E-21" ixz="-7.1817349065269E-22" iyy="7.69100314106116E-07" iyz="6.74715432769696E-07" izz="2.30315190420171E-06" />
        </inertial>
        <visual>
            <origin rpy="0 0 0" xyz="0 0 0" />
            <geometry>
                <mesh filename="package://robotiq_2f_140_gripper_visualization/meshes/robotiq_arg2f_140_inner_finger.stl" />
            </geometry>
            <material name="">
                <color rgba="0.1 0.1 0.1 1" />
            </material>
        </visual>
        <collision>
            <origin rpy="0 0 0" xyz="0 0 0" />
            <geometry>
                <mesh filename="package://robotiq_2f_140_gripper_visualization/meshes/robotiq_arg2f_140_inner_finger.stl" />
            </geometry>
        </collision>
    </link>
    <link name="left_inner_knuckle">
        <inertial>
            <origin rpy="0 0 0" xyz="0.000123011831763771 0.0507850843201817 0.00103968640075166" />
            <mass value="0.0271177346495152" />
            <inertia ixx="2.61910379223783E-05" ixy="-2.43616858946494E-07" ixz="-6.37789906117123E-09" iyy="2.8270243746167E-06" iyz="-5.37200748039765E-07" izz="2.83695868220296E-05" />
        </inertial>
        <visual>
            <origin rpy="0 0 0" xyz="0 0 0" />
            <geometry>
                <mesh filename="package://robotiq_2f_140_gripper_visualization/meshes/robotiq_arg2f_140_inner_knuckle.stl" />
            </geometry>
            <material name="">
                <color rgba="0.1 0.1 0.1 1" />
            </material>
        </visual>
        <collision>
            <origin rpy="0 0 0" xyz="0 0 0" />
            <geometry>
                <mesh filename="package://robotiq_2f_140_gripper_visualization/meshes/robotiq_arg2f_140_inner_knuckle.stl" />
            </geometry>
        </collision>
    </link>
    <link name="right_outer_knuckle">
        <inertial>
            <origin rpy="0 0 0" xyz="-0.000200000000003065 0.0199435877845359 0.0292245259211331" />
            <mass value="0.00853198276973456" />
            <inertia ixx="2.89328108496468E-06" ixy="-1.57935047237397E-19" ixz="-1.93980378593255E-19" iyy="1.86719750325683E-06" iyz="-1.21858577871576E-06" izz="1.21905238907251E-06" />
        </inertial>
        <visual>
            <origin rpy="0 0 0" xyz="0 0 0" />
            <geometry>
                <mesh filename="package://robotiq_2f_140_gripper_visualization/meshes/robotiq_arg2f_140_outer_knuckle.stl" />
            </geometry>
            <material name="">
                <color rgba="0.792156862745098 0.819607843137255 0.933333333333333 1" />
            </material>
        </visual>
        <collision>
            <origin rpy="0 0 0" xyz="0 0 0" />
            <geometry>
                <mesh filename="package://robotiq_2f_140_gripper_visualization/meshes/robotiq_arg2f_140_outer_knuckle.stl" />
            </geometry>
        </collision>
    </link>
    <link name="right_outer_finger">
        <inertial>
            <origin rpy="0 0 0" xyz="0.00030115855001899 0.0373907951953854 -0.0208027427000385" />
            <mass value="0.022614240507152" />
            <inertia ixx="1.52518312458174E-05" ixy="9.76583423954399E-10" ixz="-5.43838577022588E-10" iyy="6.17694243867776E-06" iyz="6.78636130740228E-06" izz="1.16494917907219E-05" />
        </inertial>
        <visual>
            <origin rpy="0 0 0" xyz="0 0 0" />
            <geometry>
                <mesh filename="package://robotiq_2f_140_gripper_visualization/meshes/robotiq_arg2f_140_outer_finger.stl" />
            </geometry>
            <material name="">
                <color rgba="0.1 0.1 0.1 1" />
            </material>
        </visual>
        <collision>
            <origin rpy="0 0 0" xyz="0 0 0" />
            <geometry>
                <mesh filename="package://robotiq_2f_140_gripper_visualization/meshes/robotiq_arg2f_140_outer_finger.stl" />
            </geometry>
        </collision>
    </link>
    <link name="right_inner_finger">
        <inertial>
            <origin rpy="0 0 0" xyz="0.000299999999999317 0.0160078233491243 -0.0136945669206257" />
            <mass value="0.0104003125914103" />
            <inertia ixx="2.71909453810972E-06" ixy="1.35402465472579E-21" ixz="-7.1817349065269E-22" iyy="7.69100314106116E-07" iyz="6.74715432769696E-07" izz="2.30315190420171E-06" />
        </inertial>
        <visual>
            <origin rpy="0 0 0" xyz="0 0 0" />
            <geometry>
                <mesh filename="package://robotiq_2f_140_gripper_visualization/meshes/robotiq_arg2f_140_inner_finger.stl" />
            </geometry>
            <material name="">
                <color rgba="0.1 0.1 0.1 1" />
            </material>
        </visual>
        <collision>
            <origin rpy="0 0 0" xyz="0 0 0" />
            <geometry>
                <mesh filename="package://robotiq_2f_140_gripper_visualization/meshes/robotiq_arg2f_140_inner_finger.stl" />
            </geometry>
        </collision>
    </link>
    <link name="right_inner_knuckle">
        <inertial>
            <origin rpy="0 0 0" xyz="0.000123011831763771 0.0507850843201817 0.00103968640075166" />
            <mass value="0.0271177346495152" />
            <inertia ixx="2.61910379223783E-05" ixy="-2.43616858946494E-07" ixz="-6.37789906117123E-09" iyy="2.8270243746167E-06" iyz="-5.37200748039765E-07" izz="2.83695868220296E-05" />
        </inertial>
        <visual>
            <origin rpy="0 0 0" xyz="0 0 0" />
            <geometry>
                <mesh filename="package://robotiq_2f_140_gripper_visualization/meshes/robotiq_arg2f_140_inner_knuckle.stl" />
            </geometry>
            <material name="">
                <color rgba="0.1 0.1 0.1 1" />
            </material>
        </visual>
        <collision>
            <origin rpy="0 0 0" xyz="0 0 0" />
            <geometry>
                <mesh filename="package://robotiq_2f_140_gripper_visualization/meshes/robotiq_arg2f_140_inner_knuckle.stl" />
            </geometry>
        </collision>
    </link>
    <joint name="finger_joint" type="revolute">
        <origin rpy="2.2957963267948966 0 0" xyz="0 -0.030601 0.054905" />
        <parent link="robotiq_arg2f_base_link" />
        <child link="left_outer_knuckle" />
        <axis xyz="-1 0 0" />
        <limit effort="1000" lower="0" upper="0.775" velocity="2.0" />
    </joint>
    <joint name="left_outer_finger_joint" type="fixed">
        <origin rpy="0 0 0" xyz="0 0.01821998610742 0.0260018192872234" />
        <parent link="left_outer_knuckle" />
        <child link="left_outer_finger" />
        <axis xyz="1 0 0" />
    </joint>
    <joint name="left_inner_knuckle_joint" type="revolute">
        <origin rpy="2.2957963267948966 0 0.0" xyz="0 -0.0127 0.06142" />
        <parent link="robotiq_arg2f_base_link" />
        <child link="left_inner_knuckle" />
        <axis xyz="1 0 0" />
        <limit effort="1000" lower="0" upper="0.8757" velocity="2.0" />
        <mimic joint="finger_joint" multiplier="-1" offset="0" />
    </joint>
    <joint name="left_inner_finger_joint" type="revolute">
        <origin rpy="-.725 0 0" xyz="0 0.0817554015893473 -0.0282203446692936" />
        <parent link="left_outer_finger" />
        <child link="left_inner_finger" />
        <axis xyz="1 0 0" />
        <limit effort="1000" lower="0" upper="0.8757" velocity="2.0" />
        <mimic joint="finger_joint" multiplier="1" offset="0" />
    </joint>
    <joint name="right_outer_knuckle_joint" type="revolute">
        <origin rpy="2.2957963267948966 0 3.141592653589793" xyz="0 0.030601 0.054905" />
        <parent link="robotiq_arg2f_base_link" />
        <child link="right_outer_knuckle" />
        <axis xyz="1 0 0" />
        <limit effort="1000" lower="0" upper="0.725" velocity="2.0" />
        <mimic joint="finger_joint" multiplier="-1" offset="0" />
    </joint>
    <joint name="right_outer_finger_joint" type="fixed">
        <origin rpy="0 0 0" xyz="0 0.01821998610742 0.0260018192872234" />
        <parent link="right_outer_knuckle" />
        <child link="right_outer_finger" />
        <axis xyz="1 0 0" />
    </joint>
    <joint name="right_inner_knuckle_joint" type="revolute">
        <origin rpy="2.2957963267948966 0 -3.141592653589793" xyz="0 0.0127 0.06142" />
        <parent link="robotiq_arg2f_base_link" />
        <child link="right_inner_knuckle" />
        <axis xyz="1 0 0" />
        <limit effort="1000" lower="0" upper="0.8757" velocity="2.0" />
        <mimic joint="finger_joint" multiplier="-1" offset="0" />
    </joint>
    <joint name="right_inner_finger_joint" type="revolute">
        <origin rpy="-.725 0 0" xyz="0 0.0817554015893473 -0.0282203446692936" />
        <parent link="right_outer_finger" />
        <child link="right_inner_finger" />
        <axis xyz="1 0 0" />
        <limit effort="1000" lower="0" upper="0.8757" velocity="2.0" />
        <mimic joint="finger_joint" multiplier="1" offset="0" />
    </joint>
    <transmission name="finger_joint_trans">
        <type>transmission_interface/SimpleTransmission</type>
        <joint name="finger_joint">
            <hardwareInterface>EffortJointInterface</hardwareInterface>
        </joint>
        <actuator name="finger_joint_motor">
            <mechanicalReduction>1</mechanicalReduction>
            <hardwareInterface>hardware_interface/EffortJointInterface</hardwareInterface>
        </actuator>
    </transmission>
    <gazebo>
        <!-- loading plugin: mimic joints works in gazebo now-->
        <plugin filename="libroboticsgroup_gazebo_mimic_joint_plugin.so" name="mimic_robotiq_140_4">
            <joint>finger_joint</joint>
            <mimicJoint>right_outer_knuckle_joint</mimicJoint>
        </plugin>
        <plugin filename="libroboticsgroup_gazebo_mimic_joint_plugin.so" name="mimic_robotiq_140_2">
            <joint>finger_joint</joint>
            <mimicJoint>left_inner_finger_joint</mimicJoint>
        </plugin>
        <plugin filename="libroboticsgroup_gazebo_mimic_joint_plugin.so" name="mimic_robotiq_140_1">
            <joint>finger_joint</joint>
            <mimicJoint>right_inner_finger_joint</mimicJoint>
        </plugin>
        <plugin filename="libroboticsgroup_gazebo_mimic_joint_plugin.so" name="mimic_robotiq_140_3">
            <joint>finger_joint</joint>
            <mimicJoint>left_inner_knuckle_joint</mimicJoint>
        </plugin>
        <plugin filename="libroboticsgroup_gazebo_mimic_joint_plugin.so" name="mimic_robotiq_140_5">
            <joint>finger_joint</joint>
            <mimicJoint>right_inner_knuckle_joint</mimicJoint>
        </plugin>
    </gazebo>
    <!--
    <transmission name="${prefix}left_inner_finger_joint_trans">
      <type>transmission_interface/SimpleTransmission</type>
      <joint name="${prefix}left_inner_finger_joint">
        <hardwareInterface>EffortJointInterface</hardwareInterface>
      </joint>
      <actuator name="${prefix}finger_joint_motor">
        <mechanicalReduction>1</mechanicalReduction>
      </actuator>
    </transmission>

    <transmission name="${prefix}left_inner_knuckle_joint_trans">
      <type>transmission_interface/SimpleTransmission</type>
      <joint name="${prefix}left_inner_knuckle_joint">
        <hardwareInterface>EffortJointInterface</hardwareInterface>
      </joint>
      <actuator name="${prefix}finger_joint_motor">
        <mechanicalReduction>1</mechanicalReduction>
      </actuator>
    </transmission>

    <transmission name="${prefix}right_inner_knuckle_joint_trans">
      <type>transmission_interface/SimpleTransmission</type>
      <joint name="${prefix}right_inner_knuckle_joint">
        <hardwareInterface>EffortJointInterface</hardwareInterface>
      </joint>
      <actuator name="${prefix}finger_joint_motor">
        <mechanicalReduction>1</mechanicalReduction>
      </actuator>
    </transmission>

    <transmission name="${prefix}right_outer_knuckle_joint_trans">
      <type>transmission_interface/SimpleTransmission</type>
      <joint name="${prefix}right_outer_knuckle_joint">
        <hardwareInterface>EffortJointInterface</hardwareInterface>
      </joint>
      <actuator name="${prefix}finger_joint_motor">
        <mechanicalReduction>1</mechanicalReduction>
      </actuator>
    </transmission>

    <transmission name="${prefix}right_inner_finger_joint_trans">
      <type>transmission_interface/SimpleTransmission</type>
      <joint name="${prefix}right_inner_finger_joint">
        <hardwareInterface>EffortJointInterface</hardwareInterface>
      </joint>
      <actuator name="${prefix}finger_joint_motor">
        <mechanicalReduction>1</mechanicalReduction>
      </actuator>
    </transmission> -->
    <transmission name="trans_left_inner_knuckle_joint">
        <type>transmission_interface/SimpleTransmission</type>
        <joint name="left_inner_knuckle_joint">
            <hardwareInterface>hardware_interface/EffortJointInterface</hardwareInterface>
        </joint>
        <actuator name="left_inner_knuckle_joint_motor">
            <hardwareInterface>hardware_interface/EffortJointInterface</hardwareInterface>
            <mechanicalReduction>1</mechanicalReduction>
        </actuator>
    </transmission>
    <transmission name="trans_left_inner_finger_joint">
        <type>transmission_interface/SimpleTransmission</type>
        <joint name="left_inner_finger_joint">
            <hardwareInterface>hardware_interface/EffortJointInterface</hardwareInterface>
        </joint>
        <actuator name="left_inner_finger_joint_motor">
            <hardwareInterface>hardware_interface/EffortJointInterface</hardwareInterface>
            <mechanicalReduction>1</mechanicalReduction>
        </actuator>
    </transmission>
    <transmission name="trans_right_outer_knuckle_joint">
        <type>transmission_interface/SimpleTransmission</type>
        <joint name="right_outer_knuckle_joint">
            <hardwareInterface>hardware_interface/EffortJointInterface</hardwareInterface>
        </joint>
        <actuator name="right_outer_knuckle_joint_motor">
            <hardwareInterface>hardware_interface/EffortJointInterface</hardwareInterface>
            <mechanicalReduction>1</mechanicalReduction>
        </actuator>
    </transmission>
    <transmission name="trans_right_inner_knuckle_joint">
        <type>transmission_interface/SimpleTransmission</type>
        <joint name="right_inner_knuckle_joint">
            <hardwareInterface>hardware_interface/EffortJointInterface</hardwareInterface>
        </joint>
        <actuator name="right_inner_knuckle_joint_motor">
            <hardwareInterface>hardware_interface/EffortJointInterface</hardwareInterface>
            <mechanicalReduction>1</mechanicalReduction>
        </actuator>
    </transmission>
    <transmission name="trans_right_inner_finger_joint">
        <type>transmission_interface/SimpleTransmission</type>
        <joint name="right_inner_finger_joint">
            <hardwareInterface>hardware_interface/EffortJointInterface</hardwareInterface>
        </joint>
        <actuator name="right_inner_finger_joint_motor">
            <hardwareInterface>hardware_interface/EffortJointInterface</hardwareInterface>
            <mechanicalReduction>1</mechanicalReduction>
        </actuator>
    </transmission>
</robot>

